<?xml version="1.0" ?>
<!-- =================================================================================== -->
<!-- |    This document was autogenerated by xacro from sis_arm.urdf.xacro             | -->
<!-- |    EDITING THIS FILE BY HAND IS NOT RECOMMENDED                                 | -->
<!-- =================================================================================== -->
<robot name="sis_arm" xmlns:xacro="http://ros.org/wiki/xacro">
  <!-- Color define -->
  <material name="blue">
    <color rgba="0 0 0.8 1"/>
  </material>
  <material name="black">
    <color rgba="0.1 0.1 0.1 1"/>
  </material>
  <material name="white">
    <color rgba="1 1 1 1"/>
  </material>
  <material name="gray">
    <color rgba="0.5 0.5 0.5 1"/>
  </material>
  <!-- end Color define -->
  <!-- end Constants define -->
  <!-- end gripper -->
  <!-- end Macro define -->
  <!-- Acrylic_base -->
  <link name="base">
    <visual>
      <geometry>
        <box size="0.15 0.15 0.0025"/>
      </geometry>
      <material name="white"/>
    </visual>
    <collision>
      <geometry>
        <box size="0.15 0.15 0.0025"/>
      </geometry>
    </collision>
    <inertial>
      <mass value="0.08"/>
      <inertia ixx="1.0" ixy="0.0" ixz="0.0" iyy="1.0" iyz="0.0" izz="1.0"/>
    </inertial>
  </link>
  <link name="pan_f3">
    <visual>
      <geometry>
        <mesh filename="package://robot_description/meshes/F3.stl" scale="0.001 0.001 0.001"/>
      </geometry>
      <material name="gray"/>
    </visual>
    <collision>
      <geometry>
        <mesh filename="package://robot_description/meshes/F3.stl" scale="0.001 0.001 0.001"/>
      </geometry>
    </collision>
    <inertial>
      <mass value="0.009"/>
      <inertia ixx="1.0" ixy="0.0" ixz="0.0" iyy="1.0" iyz="0.0" izz="1.0"/>
    </inertial>
  </link>
  <link name="pan_motor">
    <visual>
      <geometry>
        <mesh filename="package://robot_description/meshes/ax12_box.stl" scale="0.001 0.001 0.001"/>
      </geometry>
      <material name="black"/>
    </visual>
    <collision>
      <geometry>
        <mesh filename="package://robot_description/meshes/ax12_box.stl" scale="0.001 0.001 0.001"/>
      </geometry>
    </collision>
    <inertial>
      <mass value="0.0535"/>
      <inertia ixx="1.0" ixy="0.0" ixz="0.0" iyy="1.0" iyz="0.0" izz="1.0"/>
    </inertial>
  </link>
  <joint name="pan_motor_f3_joint" type="fixed">
    <parent link="pan_f3"/>
    <child link="pan_motor"/>
    <origin rpy="0 3.1415 0" xyz="0 0 -0.041"/>
  </joint>
  <!-- end Pan frame and motor -->
  <!-- Base and pan_frame joint -->
  <joint name="base_pan_f3_joint" type="fixed">
    <parent link="base"/>
    <child link="pan_f3"/>
    <origin rpy="0 3.1415 0" xyz="0 0 0.001"/>
  </joint>
  <link name="tilt_f3">
    <visual>
      <geometry>
        <mesh filename="package://robot_description/meshes/F3.stl" scale="0.001 0.001 0.001"/>
      </geometry>
      <material name="gray"/>
    </visual>
    <collision>
      <geometry>
        <mesh filename="package://robot_description/meshes/F3.stl" scale="0.001 0.001 0.001"/>
      </geometry>
    </collision>
    <inertial>
      <mass value="0.009"/>
      <inertia ixx="1.0" ixy="0.0" ixz="0.0" iyy="1.0" iyz="0.0" izz="1.0"/>
    </inertial>
  </link>
  <link name="tilt_motor">
    <visual>
      <geometry>
        <mesh filename="package://robot_description/meshes/ax12_box.stl" scale="0.001 0.001 0.001"/>
      </geometry>
      <material name="black"/>
    </visual>
    <collision>
      <geometry>
        <mesh filename="package://robot_description/meshes/ax12_box.stl" scale="0.001 0.001 0.001"/>
      </geometry>
    </collision>
    <inertial>
      <mass value="0.0535"/>
      <inertia ixx="1.0" ixy="0.0" ixz="0.0" iyy="1.0" iyz="0.0" izz="1.0"/>
    </inertial>
  </link>
  <joint name="tilt_motor_f3_joint" type="fixed">
    <parent link="tilt_f3"/>
    <child link="tilt_motor"/>
    <origin rpy="0 3.1415 0" xyz="0 0 -0.041"/>
  </joint>
  <!-- end Tilt frame and motor -->
  <!-- Pan joint -->
  <joint name="pan_joint" type="revolute">
    <axis xyz="0 0 -1"/>
    <parent link="pan_motor"/>
    <child link="tilt_f3"/>
    <limit effort="1000.0" lower="-2.616" upper="2.616" velocity="2.0"/>
    <origin rpy="0 -1.57075 1.57075" xyz="0 0.02 0"/>
  </joint>
  <!-- end pan joint -->
  <!-- Frame 2 -->
  <link name="tilt_f2">
    <visual>
      <geometry>
        <mesh filename="package://robot_description/meshes/F2.stl" scale="0.001 0.001 0.001"/>
      </geometry>
      <material name="gray"/>
    </visual>
    <collision>
      <geometry>
        <mesh filename="package://robot_description/meshes/F2.stl" scale="0.001 0.001 0.001"/>
      </geometry>
    </collision>
    <inertial>
      <mass value="0.009"/>
      <inertia ixx="1.0" ixy="0.0" ixz="0.0" iyy="1.0" iyz="0.0" izz="1.0"/>
    </inertial>
  </link>
  <!-- end frame 2 -->
  <!-- Tilt joint -->
  <joint name="tilt_joint" type="revolute">
    <axis xyz="0 1 0"/>
    <parent link="tilt_motor"/>
    <child link="tilt_f2"/>
    <limit effort="1000.0" lower="-2.0" upper="0.8" velocity="2.0"/>
    <origin rpy="0 0 0" xyz="0 0 0"/>
  </joint>
  <link name="gripper_f3">
    <visual>
      <geometry>
        <mesh filename="package://robot_description/meshes/F3.stl" scale="0.001 0.001 0.001"/>
      </geometry>
      <material name="gray"/>
    </visual>
    <collision>
      <geometry>
        <mesh filename="package://robot_description/meshes/F3.stl" scale="0.001 0.001 0.001"/>
      </geometry>
    </collision>
    <inertial>
      <mass value="0.009"/>
      <inertia ixx="1.0" ixy="0.0" ixz="0.0" iyy="1.0" iyz="0.0" izz="1.0"/>
    </inertial>
  </link>
  <link name="gripper_motor">
    <visual>
      <geometry>
        <mesh filename="package://robot_description/meshes/ax12_box.stl" scale="0.001 0.001 0.001"/>
      </geometry>
      <material name="black"/>
    </visual>
    <collision>
      <geometry>
        <mesh filename="package://robot_description/meshes/ax12_box.stl" scale="0.001 0.001 0.001"/>
      </geometry>
    </collision>
    <inertial>
      <mass value="0.0535"/>
      <inertia ixx="1.0" ixy="0.0" ixz="0.0" iyy="1.0" iyz="0.0" izz="1.0"/>
    </inertial>
  </link>
  <joint name="gripper_motor_f3_joint" type="fixed">
    <parent link="gripper_f3"/>
    <child link="gripper_motor"/>
    <origin rpy="0 3.1415 0" xyz="0 0 -0.041"/>
  </joint>
  <!-- end Gripper frame and motor -->
  <!-- Frame joint -->
  <joint name="frame_2_frame_3_joint" type="fixed">
    <parent link="tilt_f2"/>
    <child link="gripper_f3"/>
    <origin rpy="0 3.1415 -1.57075" xyz="0 0 0.0265"/>
  </joint>
  <link name="gripper_base">
    <visual>
      <geometry>
        <mesh filename="package://robot_description/meshes/pincher_finger_base.stl" scale="0.01 0.01 0.01"/>
      </geometry>
      <material name="black"/>
    </visual>
    <collision>
      <geometry>
        <mesh filename="package://robot_description/meshes/pincher_finger_base.stl" scale="0.01 0.01 0.01"/>
      </geometry>
    </collision>
    <inertial>
      <mass value="0.01"/>
      <inertia ixx="1.0" ixy="0.0" ixz="0.0" iyy="1.0" iyz="0.0" izz="1.0"/>
    </inertial>
  </link>
  <joint name="gripper_motor_base" type="fixed">
    <parent link="gripper_motor"/>
    <child link="gripper_base"/>
    <origin rpy="0 0 0" xyz="0 0.0177 0.001"/>
  </joint>
  <link name="left_finger">
    <visual>
      <geometry>
        <mesh filename="package://robot_description/meshes/pincher_finger.stl" scale="0.01 0.01 0.01"/>
      </geometry>
      <material name="black"/>
    </visual>
    <collision>
      <geometry>
        <mesh filename="package://robot_description/meshes/pincher_finger.stl" scale="0.01 0.01 0.01"/>
      </geometry>
    </collision>
    <inertial>
      <mass value="0.005"/>
      <inertia ixx="1.0" ixy="0.0" ixz="0.0" iyy="1.0" iyz="0.0" izz="1.0"/>
    </inertial>
  </link>
  <joint name="left_finger_joint" type="prismatic">
    <origin rpy="1.57075 0 3.1415" xyz="-0.0185 0.001 0"/>
    <axis rpy="0 0 0" xyz="-1 0 0"/>
    <limit effort="1000.0" lower="0.0" upper="0.012" velocity="1.0"/>
    <parent link="gripper_base"/>
    <child link="left_finger"/>
  </joint>
  <link name="right_finger">
    <visual>
      <geometry>
        <mesh filename="package://robot_description/meshes/pincher_finger.stl" scale="0.01 0.01 0.01"/>
      </geometry>
      <material name="black"/>
    </visual>
    <collision>
      <geometry>
        <mesh filename="package://robot_description/meshes/pincher_finger.stl" scale="0.01 0.01 0.01"/>
      </geometry>
    </collision>
    <inertial>
      <mass value="0.005"/>
      <inertia ixx="1.0" ixy="0.0" ixz="0.0" iyy="1.0" iyz="0.0" izz="1.0"/>
    </inertial>
  </link>
  <joint name="right_finger_joint" type="prismatic">
    <origin rpy="-1.57075 0 0" xyz="0.0185 0.001 0"/>
    <axis rpy="0 0 0" xyz="-1 0 0"/>
    <limit effort="1000.0" lower="0.0" upper="0.012" velocity="1.0"/>
    <parent link="gripper_base"/>
    <child link="right_finger"/>
  </joint>
  <!-- end gripper -->
  <!-- TCP -->
  <link name="tcp"/>
  <!-- end TCP -->
  <!-- gripper base to tcp joint -->
  <joint name="gripper_base_tcp_joint" type="fixed">
    <parent link="gripper_base"/>
    <child link="tcp"/>
    <origin rpy="-1.57075 0 1.57075" xyz="0 0.035 0"/>
  </joint>
  <!-- end gripper base to tcp joint -->
</robot>

